Workbook

Sheet BESS_technical
B1: BESS_sim.py version 2022.12.20
B3: BESS technical parameters | C3: BESS_1 | D3: BESS_2 | E3: Unit | F3: Comments
B4: Rated active power for up-reg. | C4: 80 | D4: 60 | E4: MW | F4: output to the grid or discharge
B5: Rated active power for down-reg. | C5: 80 | D5: 60 | E5: MW | F5: input from the grid or charge
B6: Rated energy capacity (discharge = to the grid) | C6: 160 | D6: 120 | E6: MWh
B7: Min SOC limit / permitted DOD | C7: 10 | D7: 10 | E7: %
B8: Max SOC limit / permitted DOC | C8: 90 | D8: 90 | E8: %
B9: Charging efficiency | C9: 0.95 | D9: 0.95 | E9: [0–1] | F9: including all components (i.e. [Energy into battery] / [Energy from grid])
B10: Discharging efficiency | C10: 0.95 | D10: 0.95 | E10: [0–1] | F10: including all components (i.e. [Energy to grid] / [Energy from battery])
B11: Round-trip efficiency (AC/AC) | E11: [0–1] | F11: including all components (i.e. [Energy to grid] / [Energy from grid])
B12: Self-discharge | C12: 0.08 | D12: 0.08 | E12: %/day | F12: losses not included in efficiency, occurring regardless of BESS being idle or active, expressed as % of SOC per day
B13: Min cycling per 24 hours | E13: cycle/day | F13: minimum amount of energy to be discharged within any 24-h period, 1 cycle = sum discharge equal to rated capacity
B14: Ensure min cycling? | C14: no | F14: if no, only reports if min cycling has failed to occur; if yes, attempts BESS_1 <-> BESS_2 cycling for min condition
I15: SOC0 | J15: SOC0 | K15: init_unit
B16: BESS simulation settings | C16: BESS_1 | D16: BESS_2 | I16: BESS1 | J16: BESS2 | K16: BESS1 | L16: BESS2
B17: Initial state of charge | C17: 50 | D17: 50 | E17: % | H17: min | I17: =IF(E7="%",C7/100*C6,C7) -> 16 | J17: =IF(E7="%",D7/100*D6,D7) -> 12 | K17: =IF(E17="%",I17/C$6*100,I17) -> 10 | L17: =IF(E17="%",J17/D$6*100,J17) -> 10
B18: Storage qualified as LER | C18: yes | D18: yes | F18: Limited energy reservoir | H18: max | I18: =IF(E8="%",C8/100*C6,C8) -> 144 | J18: =IF(E8="%",D8/100*D6,D8) -> 108 | K18: =IF(E17="%",I18/C$6*100,I18) -> 90 | L18: =IF(E17="%",J18/D$6*100,J18) -> 90
B19: BESS availability | C19: yes | D19: no | F19: Select "no" if the specific BESS is to be considered unavailable during the simulation
B20: LER SOC management strategy | C20: Active | D20: Conservative | F20: Conservative strategy: to fulfill minimum LER requirements; Active strategy: manage SOC like a non-LER resource
B21: Simulation time resolution | C21: 1 | E21: min
B22: Intraday bid acceptance probability | C22: 100 | E22: %
B24: Frequency input file | C24: FI_2022_scenario_frequency.csv | F24: Specify the csv, xls or xlsx input file name.
B25: FRR activation input file | C25: FI_2022_scenario_FRR.csv
B26: Scenario name for result output | C26: FI Active | F26: Specify the name for the result output files.
B28: BESS reserve provision settings | C28: BESS_1 | D28: BESS_2 | E28: BESS fleet | F28: Reserve provision to be defined for the BESS fleet or BESS 1&2 separately. The cells in red should not be left blank
B29: Uniform mandatory FCR capacity during the day | C29: yes | D29: yes | E29: n/a | F29: If no selected, provide variable FCR capacity bids for each MTU in the sheet BESS_capacity_bids
B30: Uniform mandatory FRR capacity during the day | C30: yes | D30: yes | E30: n/a | F30: If no selected, provide variable FRR UP and DOWN capacity bids for each MTU in the sheet BESS_capacity_bids
B31: Uniform mandatory FCR capacity, MW | C31: 8 | D31: 6 | E31: 8 | F31: For a uniform FCR, provide the capacity for the whole simulation period
B32: Mandatory FRR UP capacity, MW | C32: 32 | D32: 24 | E32: 32 | F32: For a uniform FRR, provide the UP capacity for the whole period
B33: Mandatory FRR DOWN capacity, MW | C33: 32 | D33: 24 | E33: 32 | F33: For a uniform FRR, provide the DOWN capacity for the whole period
B34: Allow voluntary FRR energy bids? | C34: no | D34: no | E34: n/a | F34: Select n/a for BESS 1&2 if reserve provision has been defined for the BESS fleet, and vice versa
B36: Reserve market and user settings
B37: Capacity market GCT:
B38: FCR | C38: 0.3125 | D38: @ hh:mm | E38: day before
B39: FRR | C39: 0.375
B41: Energy market GCT:
B42: FRR | C42: 25 | D42: minutes before MTU
B43: Intraday | C43: 60
B45: User decision time for bids:
B46: FCR capacity | C46: 5 | D46: minutes before GCT
...

Sheet BESS_capacity_bids
C3: =IF(OR(BESS_technical!$C$29="no",BESS_technical!$C$30="no"),BESS_technical!$C$28, IF(OR(BESS_technical!$D$29="no",BESS_technical!$D$30="no"),BESS_technical!$D$28, IF(OR(BESS_technical!$E$29="no",BESS_technical!$E$30="no"),BESS_technical!$E$28,""))) | D3: capacity (MW) per MTU | G3: =IF(OR(BESS_technical!$C$29="no",BESS_technical!$C$30="no"), IF(OR(BESS_technical!$D$29="no",BESS_technical!$D$30="no"),BESS_technical!$D$28,""), "") | H3: capacity (MW) per MTU
B4: Market time unit | C4: {=IF(IF(C$3<>"", INDEX(BESS_technical!$C$29:$E$29,0, MATCH(C$3,BESS_technical!$C$28:$E$28,0)))="no", "FCR", "")} | D4: {=IF(IF(C$3<>"", INDEX(BESS_technical!$C$30:$E$30,0, MATCH(C$3,BESS_technical!$C$28:$E$28,0)))="no", "FRR up", "")} | E4: {=IF(IF(C$3<>"", INDEX(BESS_technical!$C$30:$E$30,0, MATCH(C$3,BESS_technical!$C$28:$E$28,0)))="no", "FRR down", "")} | G4: {=IF(IF(G$3<>"", INDEX(BESS_technical!$C$29:$E$29,0, MATCH(G$3,BESS_technical!$C$28:$E$28,0)))="no", "FCR", "")} | H4: {=IF(IF(G$3<>"", INDEX(BESS_technical!$C$30:$E$30,0, MATCH(G$3,BESS_technical!$C$28:$E$28,0)))="no", "FRR up", "")} | I4: {=IF(IF(G$3<>"", INDEX(BESS_technical!$C$30:$E$30,0, MATCH(G$3,BESS_technical!$C$28:$E$28,0)))="no", "FRR down", "")}
B5: MTU 1 00:00–00:15 | C5: 8 | D5: 12 | E5: 8 | G5: 3 | H5: =30-G5 -> 27 | I5: 30
B6: MTU 2 00:15–00:30 | C6: 8 | D6: 12 | E6: 8 | G6: 3 | H6: =30-G6 -> 27 | I6: 30
B7: MTU 3 00:30–00:45 | C7: 8 | D7: 12 | E7: 8 | G7: 3 | H7: =30-G7 -> 27 | I7: 30
B8: MTU 4 00:45–01:00 | C8: 8 | D8: 12 | E8: 8 | G8: 3 | H8: =30-G8 -> 27 | I8: 30
B9: MTU 5 01:00–01:15 | C9: 8 | D9: 12 | E9: 8 | G9: 3 | H9: =30-G9 -> 27 | I9: 30
B10: MTU 6 01:15–01:30 | C10: 0 | D10: 12 | E10: 8 | G10: 3 | H10: =30-G10 -> 27 | I10: 30
B11: MTU 7 01:30–01:45 | C11: 0 | D11: 12 | E11: 8 | G11: 3 | H11: =30-G11 -> 27 | I11: 30
B12: MTU 8 01:45–02:00 | C12: 0 | D12: 12 | E12: 8 | G12: 3 | H12: =30-G12 -> 27 | I12: 30
B13: MTU 9 02:00–02:15 | C13: 8 | D13: 12 | E13: 8 | G13: 3 | H13: =30-G13 -> 27 | I13: 30
B14: MTU 10 02:15–02:30 | C14: 8 | D14: 12 | E14: 8 | G14: 3 | H14: =30-G14 -> 27 | I14: 30
B15: MTU 11 02:30–02:45 | C15: 8 | D15: 12 | E15: 8 | G15: 3 | H15: =30-G15 -> 27 | I15: 30
B16: MTU 12 02:45–03:00 | C16: 8 | D16: 12 | E16: 8 | G16: 3 | H16: =30-G16 -> 27 | I16: 30
... B100: MTU 96 23:45–00:00 | C100: 4 | D100: 8 | E100: 8 | G100: 10 | H100: =30-G100 -> 20 | I100: 20

Sheet List
B3: BESS_1 | C3: BESS_2 | D3: or BESS fleet
B4: yes | C4: yes | D4: n/a | E4: If "no", provide variable FCR capacity bids for each MTU. | F4: =OR(B4="yes",B4="no") -> TRUE
B5: yes | C5: no | D5: n/a
B6: no | C6: yes | D6: n/a
B7: no | C7: no | D7: n/a
B8: n/a | C8: n/a | D8: yes
B9: n/a | C9: n/a | D9: no
